Workbook

Sheet S00_Index
A1: S00 — WORKBOOK INDEX — Greenfield Expansion Phase II · CapEx & Supply Chain Portfolio Model
A2: Prepared by: Sourabh Tarodekar | Contact: sourabh232@gmail.com | Purpose: Portfolio demonstration of Engineering Program Management – CapEx & Supply Chain Operations
A4: This workbook contains synthetic sample data created for portfolio demonstration purposes only. The data does not represent proprietary or confidential information from any employer or client.
A6: ZONE LEGEND — TAB COLOR GUIDE
A7: Zone | B7: Color | C7: Category | D7: Purpose
A8: Zone 0 | B8: Gray | C8: Navigation & Governance | D8: Index, Disclaimer & Assumptions, version control
A9: Zone 1 | B9: Blue | C9: Program Foundation | D9: Equipment portfolio, supplier data, should-cost, TCO
A10: Zone 2 | B10: Green | C10: Planning & Scheduling | D10: WBS, CPM, Milestone Roadmap, deployment, capacity, demand forecast
A11: Zone 3 | B11: Orange | C11: Financial & Risk | D11: AR, cash flow, FX, scenario analysis, supply chain risk
A12: Zone 4 | B12: Purple | C12: Strategic Supply Chain | D12: Market analysis, network, sourcing, dual-source, negotiation, inventory, assets
A13: Zone 5 | B13: Red | C13: Execution & Control | D13: Gates, ECO, VDC, yield metrics, ROI tracker, scorecard, change tracker
A14: Zone 6 | B14: Teal | C14: Portfolio & Capital Allocation | D14: Multi-program register, portfolio dashboard, prioritization scorecard
A16: SHEET DIRECTORY
A17: Sheet # | B17: Sheet Name (click to navigate) | C17: Zone | D17: Status | E17: What This Sheet Demonstrates | F17: Key Metrics / Outputs
A18: S00 | B18: S00_Index | C18: Zone 0 | D18: New | E18: Workbook navigation, zone guide, sheet directory | F18: This page
A19: S01 | B19: S01_Disclaimer_Assumptions | C19: Zone 0 | D19: Revised | E19: Portfolio disclaimer, global model assumptions, version control | F19: WACC=8%, Uptime=92%, FX rates, version log
A20: S02 | B20: S02_Equipment_Portfolio | C20: Zone 1 | D20: Revised | E20: Master equipment dataset for 2 programs (PRG-001, PRG-002) — costs, energy, throughput | F20: $13.87M + $2.38M CapEx across 21 platforms
A21: S03 | B21: S03_Supplier_Dataset | C21: Zone 1 | D21: Revised | E21: Supplier lead times, reliability scores, risk tiers across both programs | F21: 21 OEMs; Program ID column for portfolio rollups
A22: S04 | B22: S04_Should_Cost_Model | C22: Zone 1 | D22: Preserved | E22: First-principles should-cost by material, labour, OH, margin | F22: Should-cost vs quote variance analysis
A23: S05 | B23: S05_TCO_Downtime_Model | C23: Zone 1 | D23: Preserved | E23: 10-year TCO, energy, maintenance, downtime cost comparison | F23: NPV-based lifecycle cost comparison
A24: S06 | B24: S06_WBS | C24: Zone 2 | D24: New | E24: Work Breakdown Structure — all program workstreams and tasks | F24: 8 workstreams, 60+ work packages
A25: S07 | B25: S07_CPM_Master_Schedule | C25: Zone 2 | D25: New | E25: Critical Path Method schedule — activities, float, predecessors | F25: Critical path = 46 weeks; 39 activities
A26: S08 | B26: S08_Program_Milestone_Roadmap | C26: Zone 2 | D26: New | E26: Visual Gantt-style program roadmap — recruiter-friendly view | F26: G0 to G5 gates, Apr-2025 to Dec-2025
A27: S09 | B27: S09_Deployment_Timeline | C27: Zone 2 | D27: Revised | E27: Equipment-level deployment schedule by workstream | F27: 46-week program; 6 critical-path items
A28: S10 | B28: S10_Capacity_Planning | C28: Zone 2 | D28: Revised | E28: Equipment capacity model — throughput, utilization, bottleneck ID | F28: 1,040K units/yr capacity; 72.1% utilization
... A53: S35 | B53: S35_Portfolio_Prioritization | C53: Zone 6 | D53: New | E53: Weighted capital allocation scorecard — ranks programs for sequencing | F53: Greenfield #1 (4.25/5.0), Riverside #2 (3.15/5.0)

Sheet S34_Portfolio_Dashboard
A1: S34 — PORTFOLIO EXECUTIVE DASHBOARD — ALL PROGRAMS
A2: Portfolio Director: Sourabh Tarodekar · Aggregates every active/proposed program in S33_Portfolio_Register · All values linked live
A4: PORTFOLIO KEY PERFORMANCE INDICATORS
A5: ACTIVE + PROPOSED PROGRAMS | C5: TOTAL PORTFOLIO CAPEX | E5: TOTAL APPROVED/EST. BUDGET | G5: BLENDED SUPPLY CHAIN RISK | I5: TOTAL EQUIPMENT PLATFORMS
A6: ='S33_Portfolio_Register'!B10 | C6: ='S33_Portfolio_Register'!B11 | E6: ='S33_Portfolio_Register'!B12 | G6: ='S33_Portfolio_Register'!B13 | I6: ='S33_Portfolio_Register'!B14
A7: S33 — Portfolio Register | C7: Sum across all programs | E7: Incl. contingency + reserves | G7: Avg across all programs | I7: All programs combined
A9: PROGRAM-BY-PROGRAM COMPARISON
A10: Program | B10: Phase / Status | C10: CapEx (USD) | D10: % of Portfolio CapEx | E10: Approved/Est. Budget (USD) | F10: IRR | G10: Risk Score | H10: Equipment Platforms | I10: Payback (yrs)
A11: ='S33_Portfolio_Register'!B5 | B11: ='S33_Portfolio_Register'!G5 | C11: ='S33_Portfolio_Register'!H5 | D11: =C11/'S33_Portfolio_Register'!B11 | E11: ='S33_Portfolio_Register'!J5 | F11: ='S33_Portfolio_Register'!K5 | G11: ='S33_Portfolio_Register'!N5 | H11: ='S33_Portfolio_Register'!O5 | I11: ='S33_Portfolio_Register'!M5
A12: ='S33_Portfolio_Register'!B6 | B12: ='S33_Portfolio_Register'!G6 | C12: ='S33_Portfolio_Register'!H6 | D12: =C12/'S33_Portfolio_Register'!B11 | E12: ='S33_Portfolio_Register'!J6 | F12: ='S33_Portfolio_Register'!K6 | G12: ='S33_Portfolio_Register'!N6 | H12: ='S33_Portfolio_Register'!O6 | I12: ='S33_Portfolio_Register'!M6
A13: PORTFOLIO TOTAL | C13: =SUM(C11:C12) | D13: 1 | E13: =SUM(E11:E12) | G13: =AVERAGE(G11:G12) | H13: =SUM(H11:H12)
A15: PORTFOLIO NOTES
A16: PRG-001 (Greenfield Expansion Phase II) is fully approved and in execution — every figure above is live-linked to its 33-sheet model (S00-S32). PRG-002 (Riverside Automation Upgrade Phase I) is at FEL-2 (feasibility); its equipment, supplier, and risk data are live-linked to S02/S03/S16, but its IRR/NPV/payback are Finance's FEL-2 planning estimates pending a full TCO build-out ahead of AR submission. See S35_Portfolio_Prioritization for the capital allocation decision framework across both programs.

Sheet S33_Portfolio_Register
A1: S33 — Portfolio Register — All Active & Proposed CapEx Programs
A2: Portfolio Director: Sourabh Tarodekar | One row per program; financial and risk fields link live to each program's own data sheets (S02, S03, S16) where a supporting model exists | Program ID is the join key used across S33-S35
A4: Program ID | B4: Program Name | C4: Sponsor | D4: Program Manager | E4: Business Unit | F4: Phase / Gate | G4: Status | H4: Total CapEx — Equip+Install (USD) | I4: Contingency Reserve (USD) | J4: Total Approved Budget (USD) | K4: Estimated IRR | L4: 10-Yr NPV (USD) | M4: Payback (yrs) | N4: Avg Supply Chain Risk Score | O4: Equipment Platforms | P4: Strategic Capacity Impact | Q4: Notes
A5: PRG-001 | B5: Greenfield Expansion Phase II | C5: Sourabh Tarodekar (Portfolio Director) | D5: Sourabh Tarodekar | E5: Semiconductor & Advanced Process Division | F5: G2 — Equipment Build & FAT (Execution) | G5: APPROVED — IN EXECUTION | H5: ='S02_Equipment_Portfolio'!B25 | I5: ='S12_AR_Summary'!F24 | J5: ='S12_AR_Summary'!F27 | K5: ='S12_AR_Summary'!B34 | L5: ='S12_AR_Summary'!B33 | M5: 4.2 | N5: ='S16_Supply_Chain_Risk'!B36 | O5: ='S02_Equipment_Portfolio'!B27 | P5: +312,000 units/yr (35% customer volume increase) | Q5: Full 33-sheet model (S00-S32); financials, schedule, and risk fully linked
A6: PRG-002 | B6: Riverside Automation Upgrade Phase I | C6: Sourabh Tarodekar (Portfolio Director) | D6: Elena Vargas | E6: Packaging & Distribution Operations | F6: FEL-2 — Feasibility (Pre-Execution) | G6: PROPOSED — AWAITING AR APPROVAL | H6: ='S02_Equipment_Portfolio'!I40+'S02_Equipment_Portfolio'!K40 | I6: =H6*0.10 | J6: =H6+I6+42000.0+95000.0 | K6: 0.168 | L6: 1850000 | M6: 3.1 | N6: ='S16_Supply_Chain_Risk'!B53 | O6: =COUNTA('S02_Equipment_Portfolio'!A34:'S02_Equipment_Portfolio'!A39) | P6: +18% packaging line throughput (~45,000 cases/day incremental) | Q6: Equipment/supplier/risk data live-linked (S02, S03, S16); IRR/NPV/payback are Finance FEL-2 estimates, not yet a full 10-yr TCO model
A9: PORTFOLIO TOTALS
A10: Active + Proposed Programs | B10: =COUNTA(A5:A6)
A11: Total Portfolio CapEx (USD) | B11: =SUM(H5:H6)
A12: Total Portfolio Approved/Estimated Budget (USD) | B12: =SUM(J5:J6)
A13: Blended Avg Supply Chain Risk Score | B13: =AVERAGE(N5:N6)
A14: Total Equipment Platforms (All Programs) | B14: =SUM(O5:O6)

Sheet S35_Portfolio_Prioritization
A1: S35 — Portfolio Prioritization — Capital Allocation Decision Framework
A2: Portfolio Director: Sourabh Tarodekar | Weighted scorecard used to rank active + proposed programs each planning cycle | Same weighting methodology as S13_Scenario_Analysis, applied program-vs-program instead of scenario-vs-scenario
A4: SCORING DIMENSION WEIGHTS & RATIONALE
A5: Dimension | B5: Weight | C5: PRG-001 Score (1-5) | D5: PRG-002 Score (1-5) | E5: Wtd PRG-001 | F5: Wtd PRG-002 | G5: Rationale
A6: Financial Return (NPV / IRR) | B6: 0.25 | C6: 5 | D6: 3 | E6: =B6*C6 | F6: =B6*D6 | G6: Greenfield's $9.5M NPV and 14.2% IRR dwarf Riverside's $1.85M/16.8% in absolute terms
A7: Strategic Fit / Business Priority | B7: 0.2 | C7: 5 | D7: 3 | E7: =B7*C7 | F7: =B7*D7 | G7: Greenfield is core capacity for the primary revenue driver; Riverside is an efficiency play
A8: Supply Chain / Execution Risk (higher score = lower risk) | B8: 0.15 | C8: 3 | D8: 4 | E8: =B8*C8 | F8: =B8*D8 | G8: Greenfield carries a HIGH-tier single-source pump risk; Riverside's risk profile is materially lighter
A9: Schedule Readiness / Time to Value | B9: 0.15 | C9: 4 | D9: 2 | E9: =B9*C9 | F9: =B9*D9 | G9: Greenfield is already at G2 execution; Riverside is still FEL-2, pre-AR
A10: Capital Efficiency (impact per $ requested) | B10: 0.15 | C10: 3 | D10: 4 | E10: =B10*C10 | F10: =B10*D10 | G10: Riverside's smaller ask and 3.1-yr payback are more capital-efficient than Greenfield's $16M ask
A11: Organizational Readiness | B11: 0.1 | C11: 5 | D11: 3 | E11: =B11*C11 | F11: =B11*D11 | G11: Greenfield has a dedicated, established program team; Riverside's PM and team are still standing up
A12: TOTAL WEIGHTED SCORE | B12: =SUM(B6:B11) | E12: =SUM(E6:E11) | F12: =SUM(F6:F11)
A14: RECOMMENDED SEQUENCING
A15: #1 Ranked Program | B15: =IF(E12>=F12,"PRG-001 — Greenfield Expansion Phase II","PRG-002 — Riverside Automation Upgrade Phase I")
A16: #1 Weighted Score | B16: =MAX(E12,F12)
A18: DECISION SUMMARY
A19: Greenfield Expansion Phase II ranks #1 (4.25/5.0) and remains the portfolio's priority commitment — it is already AR-approved and in execution, and no action changes that. Riverside Automation Upgrade Phase I ranks #2 (3.15/5.0): recommend continuing FEL-2 feasibility work and targeting AR submission once Greenfield's peak capital draw (Q3-2025, per S14_CashFlow_Model) has passed, so the two programs' spend curves don't compete for the same capital window. Riverside's lower risk profile and faster payback make it an attractive next-in-queue candidate once schedule and organizational readiness catch up to Greenfield's.

Sheet S01_Disclaimer_Assumptions
A1: S01 — Disclaimer & Global Model Assumptions
A2: Program: Greenfield Expansion Phase II | All hardcoded inputs are in BLUE — update here ONLY. All other sheets link to this sheet.
A4: This workbook contains synthetic sample data created for portfolio demonstration purposes only. The data does not represent proprietary or confidential information from any employer or client. Prepared by Sourabh Tarodekar for demonstration of Engineering Program Management – CapEx & Supply Chain Operations capabilities. Contact: sourabh232@gmail.com
A6: ENERGY & UTILITIES
A7: Parameter | B7: Value | C7: Unit | D7: Source / Basis | E7: Date Validated | F7: Notes
A8: Energy Price – Electricity | B8: 0.11 | C8: USD/kWh | D8: EIA Industrial Rate Survey – US Avg 2024 | E8: 2025-01 | F8: Used in Annual Energy Cost calculations across S02, S05 TCO model
A9: Natural Gas Price | B9: 4.8 | C9: USD/MMBtu | D9: EIA Natural Gas Industrial Price – 2024 | E9: 2025-01 | F9: Used for high-temp furnace operating cost estimation
A10: Cooling Water Cost | B10: 0.018 | C10: USD/gallon | D10: Site Utility Rate Schedule Rev C | E10: 2025-01 | F10: Applicable to chiller and process cooling loads
A11: N2 Bulk Gas Cost | B11: 0.045 | C11: USD/scf | D11: Site Utility Rate Schedule Rev C | E11: 2025-01 | F11: Applicable to gas handling system operating cost
A13: FINANCIAL & DISCOUNT ASSUMPTIONS
A14: Parameter | B14: Value | C14: Unit | D14: Source / Basis | E14: Date Validated | F14: Notes
A15: Discount Rate (WACC) | B15: 0.08 | C15: — | D15: Finance Department; WACC model approved Q4-2024 | E15: 2025-01 | F15: Used in NPV calculations; 8% reflects blended cost of capital
A16: Project Horizon | B16: 10 | C16: Years | D16: Standard CapEx lifecycle policy | E16: 2025-01 | F16: All TCO and NPV models use 10-year horizon
A17: Tax Rate (Effective) | B17: 0.21 | C17: — | D17: US Federal + State blended estimate | E17: 2025-01 | F17: Applied in AR payback model for after-tax IRR
A18: CapEx Depreciation Method | B18: MACRS 7-yr | C18: — | D18: Finance / Tax Counsel guidance | E18: 2025-01 | F18: Per AR Summary financial justification
A19: Inflation Rate | B19: 0.025 | C19: — | D19: Corporate finance planning assumption | E19: 2025-01 | F19: Used to escalate Year 2-10 OpEx in TCO model
A21: LABOR RATES
A22: Parameter | B22: Value | C22: Unit | D22: Source / Basis | E22: Date Validated | F22: Notes
A23: Fabrication Shop Rate | B23: 95 | C23: USD/hr | D23: Supplier benchmarking; 2024 MW industrial rate | E23: 2025-01 | F23: Used in Should-Cost labor model (S04)
A24: Engineering Labor Rate | B24: 120 | C24: USD/hr | D24: Internal engineering rate card Rev 2024 | E24: 2025-01 | F24: Used in NRE and program labor estimates
A25: Installation Labor Rate | B25: 85 | C25: USD/hr | D25: Facilities contractor rate card | E25: 2025-01 | F25: Used in on-site installation cost estimates
A26: Field Service Rate (Supplier) | B26: 175 | C26: USD/hr | D26: Supplier FSE rate benchmark | E26: 2025-01 | F26: Used in downtime / MTTR cost modelling
A28: EQUIPMENT PERFORMANCE
A29: Parameter | B29: Value | C29: Unit | D29: Source / Basis | E29: Date Validated | F29: Notes
A30: Equipment Uptime Target | B30: 0.92 | C30: — | D30: Program engineering specification | E30: 2025-01 | F30: 92% uptime = 608 downtime hrs/yr basis for MTBF model
A31: Planned Maintenance Downtime | B31: 0.04 | C31: — | D31: Maintenance planning schedule | E31: 2025-01 | F31: 4% of annual hours allocated to preventive maintenance
A32: Process Yield Assumption | B32: 0.96 | C32: — | D32: Engineering process spec | E32: 2025-01 | F32: Used in capacity model to calculate effective throughput
A33: Production Value per Hour | B33: 4500 | C33: USD/hr | D33: Finance — fully-loaded production cost model | E33: 2025-01 | F33: Downtime Cost = Value/hr × MTTR hrs
A35: SUPPLIER COST MODEL INPUTS
A36: Parameter | B36: Value | C36: Unit | D36: Source / Basis | E36: Date Validated | F36: Notes
A37: Supplier Margin – Low | B37: 0.15 | C37: — | D37: Benchmarking; competitive-bid suppliers | E37: 2025-01 | F37: Lower bound; applied to multi-source components
A38: Supplier Margin – High | B38: 0.25 | C38: — | D38: Benchmarking; sole-source suppliers | E38: 2025-01 | F38: Upper bound; applied to single-source components
A39: Material Scrap Factor – Low | B39: 0.05 | C39: — | D39: Engineering; precision machined parts | E39: 2025-01 | F39: 5% scrap on raw material purchases
A40: Material Scrap Factor – High | B40: 0.08 | C40: — | D40: Engineering; cast / welded assemblies | E40: 2025-01 | F40: 8% scrap on complex fabrications
A41: Material Price – Steel (304 SS) | B41: 3.8 | C41: USD/kg | D41: Metal bulletin Q1-2025 | E41: 2025-01 | F41: Used in vacuum chamber and furnace body cost estimates
A42: Material Price – Aluminum | B42: 4.2 | C42: USD/kg | D42: Metal bulletin Q1-2025 | E42: 2025-01 | F42: Used in robotics frame and structural components
A43: Material Price – Copper | B43: 9.5 | C43: USD/kg | D43: COMEX spot Q1-2025 | E43: 2025-01 | F43: Used in transformer winding and electrical bus cost estimates
A45: DEPLOYMENT TIMELINE ASSUMPTIONS
A46: Parameter | B46: Value | C46: Unit | D46: Source / Basis | E46: Date Validated | F46: Notes
A47: Supplier Manufacturing Duration | B47: 20 | C47: Weeks | D47: Program schedule baseline Rev 1.0 | E47: 2025-01 | F47: Range: 16–24 wks depending on equipment complexity
...

Sheet S02_Equipment_Portfolio
A1: S02 — CapEx Equipment Portfolio Dataset — Advanced Manufacturing Program
A2: Fiscal Year: 2025 | Portfolio Director: Sourabh Tarodekar | Status: Active | Blue = Hardcoded Input · Black = Formula · Green = Cross-sheet Link | Program ID column (right-most) enables portfolio-wide SUMIFS rollups in S33-S35
A4: Equip. ID | B4: Category | C4: Tool Type / Model | D4: Supplier | E4: Region | F4: Ccy | G4: Unit Cost (USD) | H4: Qty | I4: Total Equip. Cost (USD) | J4: Install Cost/Unit (USD) | K4: Install Total (USD) | L4: Life (yrs) | M4: Energy (kWh/hr) | N4: Annual Maint. Rate (%) | O4: Throughput (u/hr) | P4: Op Hrs/Yr | Q4: Annual Energy Cost (USD) | R4: Engineering Notes | S4: Program ID
A5: EQ-001 | B5: Vacuum Pump System | C5: Dry Screw Vacuum Pump – 250 m³/hr | D5: Edwards Vacuum | E5: UK | F5: EUR | G5: 185000 | H5: 4 | I5: =G5*H5 | J5: 22000 | K5: =J5*H5 | L5: 12 | M5: 18.5 | N5: 0.06 | O5: 0 | P5: 8320 | Q5: =M5*P5*'S01_Disclaimer_Assumptions'!$B$8 | R5: Requires N2 purge line; facility electrical upgrade needed prior to installation | S5: PRG-001
A6: EQ-002 | B6: Vacuum Pump System | C6: Turbomolecular Pump Assembly – 2000 L/s | D6: Pfeiffer Vacuum | E6: DE | F6: EUR | G6: 310000 | H6: 3 | I6: =G6*H6 | J6: 28000 | K6: =J6*H6 | L6: 10 | M6: 12 | N6: 0.05 | O6: 0 | P6: 8320 | Q6: =M6*P6*'S01_Disclaimer_Assumptions'!$B$8 | R6: Single-source supplier; no qualified alt vendor as of Q1-2025; lead time under review | S6: PRG-001
A7: EQ-003 | B7: High-Temp Furnace | C7: Tube Furnace System – 1200°C / 8-zone | D7: Thermco Systems | E7: USA | F7: USD | G7: 520000 | H7: 2 | I7: =G7*H7 | J7: 45000 | K7: =J7*H7 | L7: 15 | M7: 95 | N7: 0.04 | O7: 24 | P7: 8320 | Q7: =M7*P7*'S01_Disclaimer_Assumptions'!$B$8 | R7: FAT to be conducted at supplier site in Austin, TX; includes process recipe transfer | S7: PRG-001
A8: EQ-004 | B8: High-Temp Furnace | C8: Batch Oxidation Furnace – 1100°C | D8: Tokyo Electron Ltd | E8: JP | F8: JPY | G8: 680000 | H8: 2 | I8: =G8*H8 | J8: 52000 | K8: =J8*H8 | L8: 15 | M8: 110 | N8: 0.045 | O8: 18 | P8: 8320 | Q8: =M8*P8*'S01_Disclaimer_Assumptions'!$B$8 | R8: JPY-denominated; FX hedge required; import duty ~3.2%; installation requires crane lift | S8: PRG-001
A9: EQ-005 | B9: Robotics / Automation | C9: 6-Axis Wafer Transfer Robot – SCARA | D9: Brooks Automation | E9: USA | F9: USD | G9: 275000 | H9: 6 | I9: =G9*H9 | J9: 18000 | K9: =J9*H9 | L9: 10 | M9: 4.2 | N9: 0.05 | O9: 120 | P9: 8320 | Q9: =M9*P9*'S01_Disclaimer_Assumptions'!$B$8 | R9: Software integration with fab MES required; vendor to supply integration team on-site | S9: PRG-001
A10: EQ-006 | B10: Robotics / Automation | C10: Overhead Track Conveyor – 50m loop | D10: Daifuku | E10: JP | F10: JPY | G10: 420000 | H10: 1 | I10: =G10*H10 | J10: 85000 | K10: =J10*H10 | L10: 12 | M10: 22 | N10: 0.04 | O10: 0 | P10: 8320 | Q10: =M10*P10*'S01_Disclaimer_Assumptions'!$B$8 | R10: Single installation; civil works for track mounts included in install cost estimate | S10: PRG-001
A11: EQ-007 | B11: Gas Handling System | C11: Process Gas Cabinet – 6-zone manifold | D11: Air Liquide Engineering | E11: FR | F11: EUR | G11: 195000 | H11: 4 | I11: =G11*H11 | J11: 32000 | K11: =J11*H11 | L11: 12 | M11: 0.8 | N11: 0.06 | O11: 0 | P11: 8320 | Q11: =M11*P11*'S01_Disclaimer_Assumptions'!$B$8 | R11: Hazmat classified; requires local regulatory permit; supplier quote under negotiation | S11: PRG-001
A12: EQ-008 | B12: Gas Handling System | C12: Bulk Gas Storage & Delivery – N2/O2/Ar | D12: Linde Engineering | E12: DE | F12: EUR | G12: 340000 | H12: 1 | I12: =G12*H12 | J12: 120000 | K12: =J12*H12 | L12: 20 | M12: 2.5 | N12: 0.03 | O12: 0 | P12: 8320 | Q12: =M12*P12*'S01_Disclaimer_Assumptions'!$B$8 | R12: Facility infrastructure tie-in; utility coordination required with site civil team | S12: PRG-001
A13: EQ-009 | B13: PLC Control System | C13: Distributed Control System – Siemens S7-1500 | D13: Siemens AG | E13: DE | F13: EUR | G13: 165000 | H13: 5 | I13: =G13*H13 | J13: 15000 | K13: =J13*H13 | L13: 10 | M13: 1.2 | N13: 0.07 | O13: 0 | P13: 8320 | Q13: =M13*P13*'S01_Disclaimer_Assumptions'!$B$8 | R13: Software license included; annual subscription renewal at $12K/system; cybersecurity review pending | S13: PRG-001
A14: EQ-010 | B14: PLC Control System | C14: SCADA Integration Platform – Ignition | D14: Inductive Automation | E14: USA | F14: USD | G14: 85000 | H14: 3 | I14: =G14*H14 | J14: 8000 | K14: =J14*H14 | L14: 8 | M14: 0.5 | N14: 0.08 | O14: 0 | P14: 8320 | Q14: =M14*P14*'S01_Disclaimer_Assumptions'!$B$8 | R14: Server hardware separate line item; IT/OT network segmentation required by InfoSec | S14: PRG-001
A15: EQ-011 | B15: Facility Infra – Power | C15: Dry-Type Transformer – 2 MVA / 480V | D15: ABB Ltd | E15: CH | F15: USD | G15: 210000 | H15: 2 | I15: =G15*H15 | J15: 35000 | K15: =J15*H15 | L15: 25 | M15: 0 | N15: 0.02 | O15: 0 | P15: 8760 | Q15: =M15*P15*'S01_Disclaimer_Assumptions'!$B$8 | R15: Component reused from prior program (legacy); refurbishment cost included in install | S15: PRG-001
A16: EQ-012 | B16: Facility Infra – Cooling | C16: Process Chiller System – 200 kW | D16: Daikin Applied | E16: JP | F16: JPY | G16: 295000 | H16: 3 | I16: =G16*H16 | J16: 40000 | K16: =J16*H16 | L16: 15 | M16: 68 | N16: 0.05 | O16: 0 | P16: 8760 | Q16: =M16*P16*'S01_Disclaimer_Assumptions'!$B$8 | R16: Glycol loop design pending; coordinate with mechanical engineering; JPY FX risk noted | S16: PRG-001
... A19: EQ-015 | B19: Robotics / Automation | C19: AMR Fleet – Autonomous Mobile Robots (×10) | D19: Mobile Industrial Robots (MiR) | E19: DK | F19: EUR | G19: 380000 | H19: 1 | I19: =G19*H19 | J19: 45000 | K19: =J19*H19 | L19: 8 | M19: 6 | N19: 0.06 | O19: 0 | P19: 8320 | Q19: =M19*P19*'S01_Disclaimer_Assumptions'!$B$8 | R19: Fleet management software license included; Wi-Fi infrastructure upgrade required | S19: PRG-001
A20: PRG-001 TOTAL — Greenfield Expansion Phase II | H20: =SUM(H5:H19) | I20: =SUM(I5:I19) | K20: =SUM(K5:K19) | Q20: =SUM(Q5:Q19)
A22: PRG-001 SUMMARY STATISTICS — Greenfield Expansion Phase II
A23: Total Equipment Purchase Cost (USD) | B23: =I20
A24: Total Installation Cost (USD) | B24: =K20
A25: Total Portfolio CapEx (USD) | B25: =B23+B24
A26: Total Annual Energy Cost (USD) | B26: =Q20
A27: Number of Equipment Platforms | B27: =COUNTA(A5:A19)
A28: Total Equipment Units | B28: =H20
A29: Average Unit Cost (USD) | B29: =AVERAGE(G5:G19)
A30: Highest Unit Cost Item (USD) | B30: =MAX(G5:G19)
A32: PRG-002 EQUIPMENT — Riverside Automation Upgrade Phase I
A33: Equip. ID | B33: Category | C33: Tool Type / Model | D33: Supplier | E33: Region | F33: Ccy | G33: Unit Cost (USD) | H33: Qty | I33: Total Equip. Cost (USD) | J33: Install Cost/Unit (USD) | K33: Install Total (USD) | L33: Life (yrs) | M33: Energy (kWh/hr) | N33: Annual Maint. Rate (%) | O33: Throughput (u/hr) | P33: Op Hrs/Yr | Q33: Annual Energy Cost (USD) | R33: Engineering Notes | S33: Program ID
A34: RV-001 | B34: Robotics / Automation | C34: Palletizing Robot – 6-Axis, 40kg payload | D34: Fanuc America | E34: USA | F34: USD | G34: 165000 | H34: 2 | I34: =G34*H34 | J34: 20000 | K34: =J34*H34 | L34: 10 | M34: 3.8 | N34: 0.05 | O34: 0 | P34: 6240 | Q34: =M34*P34*'S01_Disclaimer_Assumptions'!$B$8 | R34: Replaces manual end-of-line palletizing; guarding and safety scanner included in install | S34: PRG-002
A35: RV-002 | B35: Packaging Automation | C35: Case Packer / Cartoning System | D35: Krones AG | E35: DE | F35: EUR | G35: 410000 | H35: 1 | I35: =G35*H35 | J35: 55000 | K35: =J35*H35 | L35: 12 | M35: 14 | N35: 0.05 | O35: 0 | P35: 6240 | Q35: =M35*P35*'S01_Disclaimer_Assumptions'!$B$8 | R35: Single-source specialized cartoning technology; no qualified alt vendor identified | S35: PRG-002
A36: RV-003 | B36: Robotics / Automation | C36: AGV Fleet – Tow/Unit Load (×6) | D36: Fetch Robotics | E36: USA | F36: USD | G36: 85000 | H36: 6 | I36: =G36*H36 | J36: 8000 | K36: =J36*H36 | L36: 8 | M36: 1.1 | N36: 0.06 | O36: 0 | P36: 6240 | Q36: =M36*P36*'S01_Disclaimer_Assumptions'!$B$8 | R36: Fleet management software license included; warehouse Wi-Fi survey required pre-deployment | S36: PRG-002
A37: RV-004 | B37: Quality / Automation | C37: Vision Inspection System (×3) | D37: Cognex Corporation | E37: USA | F37: USD | G37: 62000 | H37: 3 | I37: =G37*H37 | J37: 6000 | K37: =J37*H37 | L37: 8 | M37: 0.6 | N37: 0.04 | O37: 0 | P37: 6240 | Q37: =M37*P37*'S01_Disclaimer_Assumptions'!$B$8 | R37: In-line case/label inspection; integrates with existing MES via OPC-UA | S37: PRG-002
A38: RV-005 | B38: PLC Control System | C38: Warehouse Control System Integration | D38: Rockwell Automation | E38: USA | F38: USD | G38: 145000 | H38: 1 | I38: =G38*H38 | J38: 25000 | K38: =J38*H38 | L38: 10 | M38: 1 | N38: 0.06 | O38: 0 | P38: 6240 | Q38: =M38*P38*'S01_Disclaimer_Assumptions'!$B$8 | R38: Integrates AGV fleet, conveyor, and WMS; software license + 1yr support included | S38: PRG-002
A39: RV-006 | B39: Material Handling | C39: Conveyor & Sortation System | D39: Dematic Corp | E39: USA | F39: USD | G39: 520000 | H39: 1 | I39: =G39*H39 | J39: 95000 | K39: =J39*H39 | L39: 15 | M39: 26 | N39: 0.04 | O39: 0 | P39: 6240 | Q39: =M39*P39*'S01_Disclaimer_Assumptions'!$B$8 | R39: Longest lead item; civil floor anchoring required; phased cutover to avoid line downtime | S39: PRG-002
A40: PRG-002 TOTAL — Riverside Automation Upgrade Phase I | H40: =SUM(H34:H39) | I40: =SUM(I34:I39) | K40: =SUM(K34:K39) | Q40: =SUM(Q34:Q39)

Sheet S03_Supplier_Dataset
A1: S03 — Supplier & Supply Chain Dataset — Advanced Manufacturing CapEx Program
A2: Last Updated: 2025-Q3 | Owner: Supply Chain / Sourcing Team | Risk Score = (Current LT ÷ Standard LT) × (100 − Reliability Score) | Risk Tier: LOW < 5 | MODERATE 5–15 | HIGH > 15 | Program ID column enables portfolio-wide rollups
A4: Supplier | B4: Component Type | C4: Equip. Ref | D4: Region | E4: Ccy | F4: Std LT (wks) | G4: Current LT (wks) | H4: LT Delta (wks) | I4: Reliability (0-100) | J4: Single Source Risk | K4: Alt Supplier Available | L4: Calc. Risk Score | M4: Risk Tier | N4: Engineering Notes | O4: Program ID
A5: Edwards Vacuum | B5: Dry Screw Vacuum Pumps | C5: EQ-001 | D5: UK | E5: EUR | F5: 14 | G5: 18 | H5: =G5-F5 | I5: 82 | J5: No | K5: Yes | L5: =ROUND((G5/F5)*(100-I5),2) | M5: =IF(L5>15,"HIGH",IF(L5>=5,"MODERATE","LOW")) | N5: Reliability impacted by post-Brexit logistics; alt vendor pre-qual in progress with Busch | O5: PRG-001
A6: Pfeiffer Vacuum | B6: Turbomolecular Pumps | C6: EQ-002 | D6: DE | E6: EUR | F6: 16 | G6: 26 | H6: =G6-F6 | I6: 88 | J6: Yes | K6: No | L6: =ROUND((G6/F6)*(100-I6),2) | M6: =IF(L6>15,"HIGH",IF(L6>=5,"MODERATE","LOW")) | N6: CRITICAL – single source; no qualified alternative; EQ-002 delivery risk HIGH; escalate to program director | O6: PRG-001
A7: Thermco Systems | B7: High-Temp Tube Furnaces | C7: EQ-003 | D7: USA | E7: USD | F7: 18 | G7: 20 | H7: =G7-F7 | I7: 91 | J7: No | K7: Yes | L7: =ROUND((G7/F7)*(100-I7),2) | M7: =IF(L7>15,"HIGH",IF(L7>=5,"MODERATE","LOW")) | N7: Preferred supplier; strong historical performance; alt supplier (BTU International) pre-qualified | O7: PRG-001
A8: Tokyo Electron Ltd (TEL) | B8: Batch Oxidation Furnaces | C8: EQ-004 | D8: JP | E8: JPY | F8: 20 | G8: 28 | H8: =G8-F8 | I8: 85 | J8: No | K8: Yes | L8: =ROUND((G8/F8)*(100-I8),2) | M8: =IF(L8>15,"HIGH",IF(L8>=5,"MODERATE","LOW")) | N8: JPY currency risk; FX hedge executed Q4-2024; alt: Kokusai Electric pre-qualified | O8: PRG-001
A9: Brooks Automation | B9: Wafer Transfer Robots (SCARA) | C9: EQ-005 | D9: USA | E9: USD | F9: 12 | G9: 14 | H9: =G9-F9 | I9: 90 | J9: No | K9: Yes | L9: =ROUND((G9/F9)*(100-I9),2) | M9: =IF(L9>15,"HIGH",IF(L9>=5,"MODERATE","LOW")) | N9: Software integration complexity is primary risk; not supply risk; support SLA confirmed | O9: PRG-001
A10: Daifuku | B10: Overhead Conveyor Track System | C10: EQ-006 | D10: JP | E10: JPY | F10: 22 | G10: 30 | H10: =G10-F10 | I10: 83 | J10: Yes | K10: No | L10: =ROUND((G10/F10)*(100-I10),2) | M10: =IF(L10>15,"HIGH",IF(L10>=5,"MODERATE","LOW")) | N10: Single source for overhead track design; civil interface drawings required 8 wks prior to FAT | O10: PRG-001
A11: Air Liquide Engineering | B11: Process Gas Cabinets | C11: EQ-007 | D11: FR | E11: EUR | F11: 16 | G11: 22 | H11: =G11-F11 | I11: 79 | J11: No | K11: Yes | L11: =ROUND((G11/F11)*(100-I11),2) | M11: =IF(L11>15,"HIGH",IF(L11>=5,"MODERATE","LOW")) | N11: Quote under negotiation; delivery risk moderate; Matheson Gas alt supplier evaluated | O11: PRG-001
A12: Linde Engineering | B12: Bulk Gas Storage & Delivery | C12: EQ-008 | D12: DE | E12: EUR | F12: 24 | G12: 32 | H12: =G12-F12 | I12: 86 | J12: No | K12: Yes | L12: =ROUND((G12/F12)*(100-I12),2) | M12: =IF(L12>15,"HIGH",IF(L12>=5,"MODERATE","LOW")) | N12: Long procurement cycle; requires site permit coordination; 32-wk lead time confirmed by supplier | O12: PRG-001
A13: Siemens AG | B13: Distributed Control Systems | C13: EQ-009 | D13: DE | E13: EUR | F13: 10 | G13: 14 | H13: =G13-F13 | I13: 92 | J13: No | K13: Yes | L13: =ROUND((G13/F13)*(100-I13),2) | M13: =IF(L13>15,"HIGH",IF(L13>=5,"MODERATE","LOW")) | N13: Strong supply reliability; cybersecurity review adds 3-wk internal approval cycle | O13: PRG-001
A14: Inductive Automation | B14: SCADA Platform Licenses | C14: EQ-010 | D14: USA | E14: USD | F14: 4 | G14: 5 | H14: =G14-F14 | I14: 95 | J14: No | K14: Yes | L14: =ROUND((G14/F14)*(100-I14),2) | M14: =IF(L14>15,"HIGH",IF(L14>=5,"MODERATE","LOW")) | N14: Software license only; low supply risk; primary risk is IT/OT integration complexity | O14: PRG-001
A15: ABB Ltd | B15: Dry-Type Transformers | C15: EQ-011 | D15: CH | E15: USD | F15: 14 | G15: 20 | H15: =G15-F15 | I15: 87 | J15: No | K15: Yes | L15: =ROUND((G15/F15)*(100-I15),2) | M15: =IF(L15>15,"HIGH",IF(L15>=5,"MODERATE","LOW")) | N15: Component partially reused from prior program; new units on 20-wk market lead time | O15: PRG-001
A16: Daikin Applied | B16: Process Chiller Systems | C16: EQ-012 | D16: JP | E16: JPY | F16: 16 | G16: 20 | H16: =G16-F16 | I16: 89 | J16: No | K16: Yes | L16: =ROUND((G16/F16)*(100-I16),2) | M16: =IF(L16>15,"HIGH",IF(L16>=5,"MODERATE","LOW")) | N16: Glycol loop interface drawings required prior to FAT; JPY exposure monitored | O16: PRG-001
... A19: Mobile Industrial Robots (MiR) | B19: AMR Fleet – 10 Units | C19: EQ-015 | D19: DK | E19: EUR | F19: 14 | G19: 18 | H19: =G19-F19 | I19: 84 | J19: No | K19: Yes | L19: =ROUND((G19/F19)*(100-I19),2) | M19: =IF(L19>15,"HIGH",IF(L19>=5,"MODERATE","LOW")) | N19: Fleet SW license bundled; Wi-Fi site survey required 6 wks pre-installation | O19: PRG-001
A21: PRG-001 SUPPLY CHAIN RISK SUMMARY — Greenfield Expansion Phase II
A22: Avg Standard Lead Time (wks) | B22: =AVERAGE(F5:F19)
A23: Avg Current Lead Time (wks) | B23: =AVERAGE(G5:G19)
A24: Avg Lead Time Delta (wks) | B24: =AVERAGE(H5:H19)
A25: Avg Reliability Score (0-100) | B25: =AVERAGE(I5:I19)
A26: Avg Calculated Risk Score | B26: =AVERAGE(L5:L19)
A27: Max Risk Score (Worst Supplier) | B27: =MAX(L5:L19)
A28: # Single-Source Components | B28: =COUNTIF(J5:J19,"Yes")
A29: # Components with Alt Supplier | B29: =COUNTIF(K5:K19,"Yes")
A30: # HIGH Risk Tier Suppliers | B30: =COUNTIF(M5:M19,"HIGH")
A32: PRG-002 SUPPLIERS — Riverside Automation Upgrade Phase I
A33: Supplier | B33: Component Type | C33: Equip. Ref | D33: Region | E33: Ccy | F33: Std LT (wks) | G33: Current LT (wks) | H33: LT Delta (wks) | I33: Reliability (0-100) | J33: Single Source Risk | K33: Alt Supplier Available | L33: Calc. Risk Score | M33: Risk Tier | N33: Engineering Notes | O33: Program ID
A34: Fanuc America | B34: Palletizing Robots | C34: RV-001 | D34: USA | E34: USD | F34: 10 | G34: 12 | H34: =G34-F34 | I34: 91 | J34: No | K34: Yes | L34: =ROUND((G34/F34)*(100-I34),2) | M34: =IF(L34>15,"HIGH",IF(L34>=5,"MODERATE","LOW")) | N34: Deep bench of qualified integrators; low supply risk; standard robot platform | O34: PRG-002
A35: Krones AG | B35: Case Packer / Cartoning Systems | C35: RV-002 | D35: DE | E35: EUR | F35: 20 | G35: 24 | H35: =G35-F35 | I35: 86 | J35: Yes | K35: No | L35: =ROUND((G35/F35)*(100-I35),2) | M35: =IF(L35>15,"HIGH",IF(L35>=5,"MODERATE","LOW")) | N35: Single-source specialized cartoning technology; no qualified alternative identified | O35: PRG-002
A36: Fetch Robotics | B36: AGV Fleet Units | C36: RV-003 | D36: USA | E36: USD | F36: 8 | G36: 9 | H36: =G36-F36 | I36: 93 | J36: No | K36: Yes | L36: =ROUND((G36/F36)*(100-I36),2) | M36: =IF(L36>15,"HIGH",IF(L36>=5,"MODERATE","LOW")) | N36: Mature AGV platform; Locus Robotics evaluated as viable alternate | O36: PRG-002
A37: Cognex Corporation | B37: Vision Inspection Systems | C37: RV-004 | D37: USA | E37: USD | F37: 6 | G37: 7 | H37: =G37-F37 | I37: 95 | J37: No | K37: Yes | L37: =ROUND((G37/F37)*(100-I37),2) | M37: =IF(L37>15,"HIGH",IF(L37>=5,"MODERATE","LOW")) | N37: Commodity machine-vision hardware; Keyence pre-qualified as alternate | O37: PRG-002
A38: Rockwell Automation | B38: Warehouse Control System | C38: RV-005 | D38: USA | E38: USD | F38: 8 | G38: 9 | H38: =G38-F38 | I38: 94 | J38: No | K38: Yes | L38: =ROUND((G38/F38)*(100-I38),2) | M38: =IF(L38>15,"HIGH",IF(L38>=5,"MODERATE","LOW")) | N38: Strong integrator relationship; low supply risk; standard PlantPAx platform | O38: PRG-002
A39: Dematic Corp | B39: Conveyor & Sortation Systems | C39: RV-006 | D39: USA | E39: USD | F39: 16 | G39: 20 | H39: =G39-F39 | I39: 88 | J39: No | K39: Yes | L39: =ROUND((G39/F39)*(100-I39),2) | M39: =IF(L39>15,"HIGH",IF(L39>=5,"MODERATE","LOW")) | N39: Complex site-specific integration; Honeywell Intelligrated evaluated as alternate | O39: PRG-002
A41: PRG-002 SUPPLY CHAIN RISK SUMMARY — Riverside Automation Upgrade Phase I
A42: Avg Calculated Risk Score | B42: =AVERAGE(L34:L39)
A43: Max Risk Score (Worst Supplier) | B43: =MAX(L34:L39)
A44: # Single-Source Components | B44: =COUNTIF(J34:J39,"Yes")
A45: # HIGH Risk Tier Suppliers | B45: =COUNTIF(M34:M39,"HIGH")

Sheet S04_Should_Cost_Model
A1: S04 — First-Principles Should-Cost Model — Advanced Manufacturing Capital Equipment
A2: Clean-sheet cost build-up per equipment category | All inputs in BLUE | Formulas in BLACK | Cross-sheet links in GREEN | Independent cost estimate used to challenge supplier quotes and identify cost reduction opportunities.
A4: Equipment Category | B4: Cost Element | C4: Mat. Wt (kg) | D4: Mat. Price (USD/kg) | E4: Mat. Cost | F4: Labor Hrs | G4: Shop Rate | H4: Labor Cost | I4: Subcomp/Electronics | J4: Sub-Total | K4: Overhead (12%) | L4: Supplier Margin | M4: TOTAL Cost | N4: Notes
A5: Vacuum Pump System | B5: Raw Material – Stainless Steel Body | C5: 280 | D5: 3.8 | E5: =C5*D5 | F5: 0 | G5: 0 | H5: =F5*G5 | I5: 0 | J5: =E5+H5+I5 | K5: =J5*0.12 | L5: =(J5+K5)*'S01_Disclaimer_Assumptions'!$B$38 | M5: =J5+K5+L5 | N5: Precision-cast SS housing; 304SS at market rate
A6: Vacuum Pump System | B6: Machining & Fabrication Labor | C6: 0 | D6: 0 | E6: =C6*D6 | F6: 95 | G6: ='S01_Disclaimer_Assumptions'!$B$23 | H6: =F6*G6 | I6: 0 | J6: =E6+H6+I6 | K6: =J6*0.12 | L6: =(J6+K6)*'S01_Disclaimer_Assumptions'!$B$38 | M6: =J6+K6+L6 | N6: CNC turning & milling; pump body, rotor, stator components
A7: Vacuum Pump System | B7: Purchased Subcomponents – Seals/Bearings | C7: 0 | D7: 0 | E7: =C7*D7 | F7: 0 | G7: 0 | H7: =F7*G7 | I7: 18500 | J7: =E7+H7+I7 | K7: =J7*0.12 | L7: =(J7+K7)*'S01_Disclaimer_Assumptions'!$B$38 | M7: =J7+K7+L7 | N7: Ceramic bearings, PTFE seals, shaft seals; sourced from FAG/SKF
A8: Vacuum Pump System | B8: Electronics & Motor Drive System | C8: 0 | D8: 0 | E8: =C8*D8 | F8: 0 | G8: 0 | H8: =F8*G8 | I8: 22000 | J8: =E8+H8+I8 | K8: =J8*0.12 | L8: =(J8+K8)*'S01_Disclaimer_Assumptions'!$B$38 | M8: =J8+K8+L8 | N8: VFD drive, PLC I/O cards, HMI touchscreen, wiring harness
A9: Vacuum Pump System | B9: Assembly Labor | C9: 0 | D9: 0 | E9: =C9*D9 | F9: 32 | G9: ='S01_Disclaimer_Assumptions'!$B$23 | H9: =F9*G9 | I9: 0 | J9: =E9+H9+I9 | K9: =J9*0.12 | L9: =(J9+K9)*'S01_Disclaimer_Assumptions'!$B$38 | M9: =J9+K9+L9 | N9: Final assembly, alignment, internal leak test; 32 hrs per unit
A10: Vacuum Pump System | B10: Quality / Acceptance Testing | C10: 0 | D10: 0 | E10: =C10*D10 | F10: 12 | G10: ='S01_Disclaimer_Assumptions'!$B$24 | H10: =F10*G10 | I10: 0 | J10: =E10+H10+I10 | K10: =J10*0.12 | L10: =(J10+K10)*'S01_Disclaimer_Assumptions'!$B$38 | M10: =J10+K10+L10 | N10: Performance characterization, helium leak test, ultimate pressure verification
A11: High-Temp Furnace | B11: Raw Material – Inconel / Quartz / Refractory | C11: 420 | D11: 6.84 | E11: =C11*D11 | F11: 0 | G11: 0 | H11: =F11*G11 | I11: 0 | J11: =E11+H11+I11 | K11: =J11*0.12 | L11: =(J11+K11)*'S01_Disclaimer_Assumptions'!$B$38 | M11: =J11+K11+L11 | N11: Inconel 625 hot zone; quartz liner; ceramic refractory bricks
A12: High-Temp Furnace | B12: Machining & Fabrication Labor | C12: 0 | D12: 0 | E12: =C12*D12 | F12: 180 | G12: ='S01_Disclaimer_Assumptions'!$B$23 | H12: =F12*G12 | I12: 0 | J12: =E12+H12+I12 | K12: =J12*0.12 | L12: =(J12+K12)*'S01_Disclaimer_Assumptions'!$B$38 | M12: =J12+K12+L12 | N12: Welding, machining, tube bending; complex multi-zone fabrication
A13: High-Temp Furnace | B13: Purchased Subcomponents – Heating Elements | C13: 0 | D13: 0 | E13: =C13*D13 | F13: 0 | G13: 0 | H13: =F13*G13 | I13: 45000 | J13: =E13+H13+I13 | K13: =J13*0.12 | L13: =(J13+K13)*'S01_Disclaimer_Assumptions'!$B$38 | M13: =J13+K13+L13 | N13: SiC heating elements, 8-zone; Kanthal A1 backup; sourced from Kanthal
A14: High-Temp Furnace | B14: Electronics & Control Systems | C14: 0 | D14: 0 | E14: =C14*D14 | F14: 0 | G14: 0 | H14: =F14*G14 | I14: 38000 | J14: =E14+H14+I14 | K14: =J14*0.12 | L14: =(J14+K14)*'S01_Disclaimer_Assumptions'!$B$38 | M14: =J14+K14+L14 | N14: Multi-zone PID controllers, SCR power units, thermocouple arrays
A15: High-Temp Furnace | B15: Assembly Labor | C15: 0 | D15: 0 | E15: =C15*D15 | F15: 65 | G15: ='S01_Disclaimer_Assumptions'!$B$23 | H15: =F15*G15 | I15: 0 | J15: =E15+H15+I15 | K15: =J15*0.12 | L15: =(J15+K15)*'S01_Disclaimer_Assumptions'!$B$38 | M15: =J15+K15+L15 | N15: Zone assembly, insulation packing, wiring, pre-commissioning
A16: High-Temp Furnace | B16: Quality / Acceptance Testing | C16: 0 | D16: 0 | E16: =C16*D16 | F16: 20 | G16: ='S01_Disclaimer_Assumptions'!$B$24 | H16: =F16*G16 | I16: 0 | J16: =E16+H16+I16 | K16: =J16*0.12 | L16: =(J16+K16)*'S01_Disclaimer_Assumptions'!$B$38 | M16: =J16+K16+L16 | N16: Temperature uniformity survey (9-point), ramp rate validation, atmosphere leak test
A17: Robotics / Automation | B17: Raw Material – Aluminum Frame & Structure | C17: 85 | D17: 4.2 | E17: =C17*D17 | F17: 0 | G17: 0 | H17: =F17*G17 | I17: 0 | J17: =E17+H17+I17 | K17: =J17*0.12 | L17: =(J17+K17)*'S01_Disclaimer_Assumptions'!$B$38 | M17: =J17+K17+L17 | N17: 6061 AL structural extrusions, machined joints, end-effector blanks
A18: Robotics / Automation | B18: Machining & Fabrication Labor | C18: 0 | D18: 0 | E18: =C18*D18 | F18: 40 | G18: ='S01_Disclaimer_Assumptions'!$B$23 | H18: =F18*G18 | I18: 0 | J18: =E18+H18+I18 | K18: =J18*0.12 | L18: =(J18+K18)*'S01_Disclaimer_Assumptions'!$B$38 | M18: =J18+K18+L18 | N18: CNC machining of end-effectors, links, flanges; anodizing finish
A19: Robotics / Automation | B19: Purchased Subcomponents – Servo / Drive Train | C19: 0 | D19: 0 | E19: =C19*D19 | F19: 0 | G19: 0 | H19: =F19*G19 | I19: 52000 | J19: =E19+H19+I19 | K19: =J19*0.12 | L19: =(J19+K19)*'S01_Disclaimer_Assumptions'!$B$38 | M19: =J19+K19+L19 | N19: Harmonic drive reducers, servo motors, encoders; Yaskawa / Nabtesco
A20: Robotics / Automation | B20: Electronics & Vision System | C20: 0 | D20: 0 | E20: =C20*D20 | F20: 0 | G20: 0 | H20: =F20*G20 | I20: 28000 | J20: =E20+H20+I20 | K20: =J20*0.12 | L20: =(J20+K20)*'S01_Disclaimer_Assumptions'!$B$38 | M20: =J20+K20+L20 | N20: Robot controller, teach pendant, vision camera + lighting, safety scanner
A21: Robotics / Automation | B21: Software & Integration | C21: 0 | D21: 0 | E21: =C21*D21 | F21: 35 | G21: ='S01_Disclaimer_Assumptions'!$B$24 | H21: =F21*G21 | I21: 0 | J21: =E21+H21+I21 | K21: =J21*0.12 | L21: =(J21+K21)*'S01_Disclaimer_Assumptions'!$B$38 | M21: =J21+K21+L21 | N21: MES/SEMI interface SW development, recipe upload, FAT validation scripts
A22: Robotics / Automation | B22: Quality / Acceptance Testing | C22: 0 | D22: 0 | E22: =C22*D22 | F22: 10 | G22: ='S01_Disclaimer_Assumptions'!$B$24 | H22: =F22*G22 | I22: 0 | J22: =E22+H22+I22 | K22: =J22*0.12 | L22: =(J22+K22)*'S01_Disclaimer_Assumptions'!$B$38 | M22: =J22+K22+L22 | N22: Path accuracy, repeatability ±0.05mm, cycle time validation, safety relay test
A23: Gas Handling System | B23: Raw Material – 316L SS Tubing & Fittings | C23: 60 | D23: 4.56 | E23: =C23*D23 | F23: 0 | G23: 0 | H23: =F23*G23 | I23: 0 | J23: =E23+H23+I23 | K23: =J23*0.12 | L23: =(J23+K23)*'S01_Disclaimer_Assumptions'!$B$38 | M23: =J23+K23+L23 | N23: 316L EP-grade tubing, VCR fittings, valves; electropolished internal surfaces
A24: Gas Handling System | B24: Machining & Fabrication Labor | C24: 0 | D24: 0 | E24: =C24*D24 | F24: 55 | G24: ='S01_Disclaimer_Assumptions'!$B$23 | H24: =F24*G24 | I24: 0 | J24: =E24+H24+I24 | K24: =J24*0.12 | L24: =(J24+K24)*'S01_Disclaimer_Assumptions'!$B$38 | M24: =J24+K24+L24 | N24: Tube bending, orbital welding, manifold assembly; cleanroom fabrication
A25: Gas Handling System | B25: Purchased Subcomponents – Valves & Regulators | C25: 0 | D25: 0 | E25: =C25*D25 | F25: 0 | G25: 0 | H25: =F25*G25 | I25: 32000 | J25: =E25+H25+I25 | K25: =J25*0.12 | L25: =(J25+K25)*'S01_Disclaimer_Assumptions'!$B$38 | M25: =J25+K25+L25 | N25: Swagelok/Parker pneumatic valves, MFCs, pressure regulators, check valves
A26: Gas Handling System | B26: Electronics & Safety Interlock System | C26: 0 | D26: 0 | E26: =C26*D26 | F26: 0 | G26: 0 | H26: =F26*G26 | I26: 18000 | J26: =E26+H26+I26 | K26: =J26*0.12 | L26: =(J26+K26)*'S01_Disclaimer_Assumptions'!$B$38 | M26: =J26+K26+L26 | N26: Gas detection sensors, PLC safety relays, solenoid driver cards, HMI
A27: Gas Handling System | B27: Assembly & Leak Testing | C27: 0 | D27: 0 | E27: =C27*D27 | F27: 28 | G27: ='S01_Disclaimer_Assumptions'!$B$23 | H27: =F27*G27 | I27: 0 | J27: =E27+H27+I27 | K27: =J27*0.12 | L27: =(J27+K27)*'S01_Disclaimer_Assumptions'!$B$38 | M27: =J27+K27+L27 | N27: Assembly, helium leak test (<1E-9 atm·cc/s), pressure hold test, passivation
A28: Gas Handling System | B28: Quality / Acceptance Testing | C28: 0 | D28: 0 | E28: =C28*D28 | F28: 8 | G28: ='S01_Disclaimer_Assumptions'!$B$24 | H28: =F28*G28 | I28: 0 | J28: =E28+H28+I28 | K28: =J28*0.12 | L28: =(J28+K28)*'S01_Disclaimer_Assumptions'!$B$38 | M28: =J28+K28+L28 | N28: Gas purity validation, flow calibration, emergency shutoff functional test
A29: PLC Control System | B29: Purchased Subcomponents – PLC Hardware | C29: 0 | D29: 0 | E29: =C29*D29 | F29: 0 | G29: 0 | H29: =F29*G29 | I29: 42000 | J29: =E29+H29+I29 | K29: =J29*0.12 | L29: =(J29+K29)*'S01_Disclaimer_Assumptions'!$B$38 | M29: =J29+K29+L29 | N29: Siemens S7-1500 CPU, I/O cards, power supplies, HMI panel; list price
A30: PLC Control System | B30: Panel Fabrication & Wiring | C30: 0 | D30: 0 | E30: =C30*D30 | F30: 45 | G30: ='S01_Disclaimer_Assumptions'!$B$23 | H30: =F30*G30 | I30: 0 | J30: =E30+H30+I30 | K30: =J30*0.12 | L30: =(J30+K30)*'S01_Disclaimer_Assumptions'!$B$38 | M30: =J30+K30+L30 | N30: Control panel fabrication, DIN rail mounting, cable management, labeling
A31: PLC Control System | B31: Software Development & Programming | C31: 0 | D31: 0 | E31: =C31*D31 | F31: 80 | G31: ='S01_Disclaimer_Assumptions'!$B$24 | H31: =F31*G31 | I31: 0 | J31: =E31+H31+I31 | K31: =J31*0.12 | L31: =(J31+K31)*'S01_Disclaimer_Assumptions'!$B$38 | M31: =J31+K31+L31 | N31: Ladder logic/FBD development, HMI graphics, alarm management, I/O mapping
A32: PLC Control System | B32: Factory Acceptance Testing | C32: 0 | D32: 0 | E32: =C32*D32 | F32: 16 | G32: ='S01_Disclaimer_Assumptions'!$B$24 | H32: =F32*G32 | I32: 0 | J32: =E32+H32+I32 | K32: =J32*0.12 | L32: =(J32+K32)*'S01_Disclaimer_Assumptions'!$B$38 | M32: =J32+K32+L32 | N32: FAT protocol execution, point-to-point I/O check, interlock simulation
A34: SHOULD-COST SUMMARY BY EQUIPMENT CATEGORY
A35: Equipment Category | B35: Material Cost | C35: Labor Cost | D35: Subcomponents | E35: Sub-Total | F35: Overhead (12%) | G35: Supplier Margin | H35: TOTAL Should-Cost | I35: Supplier Quote (Budget Est.) | J35: Variance (Quote-SC) | K35: Variance %
A36: Vacuum Pump System | B36: =SUM(E5:E10) | C36: =SUM(H5:H10) | D36: =SUM(I5:I10) | E36: =B36+C36+D36 | F36: =E36*0.12 | G36: =(E36+F36)*'S01_Disclaimer_Assumptions'!$B$38 | H36: =E36+F36+G36 | I36: 195000 | J36: =I36-H36 | K36: =J36/H36
A37: High-Temp Furnace | B37: =SUM(E11:E16) | C37: =SUM(H11:H16) | D37: =SUM(I11:I16) | E37: =B37+C37+D37 | F37: =E37*0.12 | G37: =(E37+F37)*'S01_Disclaimer_Assumptions'!$B$38 | H37: =E37+F37+G37 | I37: 540000 | J37: =I37-H37 | K37: =J37/H37
A38: Robotics / Automation | B38: =SUM(E17:E22) | C38: =SUM(H17:H22) | D38: =SUM(I17:I22) | E38: =B38+C38+D38 | F38: =E38*0.12 | G38: =(E38+F38)*'S01_Disclaimer_Assumptions'!$B$38 | H38: =E38+F38+G38 | I38: 285000 | J38: =I38-H38 | K38: =J38/H38
A39: Gas Handling System | B39: =SUM(E23:E28) | C39: =SUM(H23:H28) | D39: =SUM(I23:I28) | E39: =B39+C39+D39 | F39: =E39*0.12 | G39: =(E39+F39)*'S01_Disclaimer_Assumptions'!$B$38 | H39: =E39+F39+G39 | I39: 205000 | J39: =I39-H39 | K39: =J39/H39
A40: PLC Control System | B40: =SUM(E29:E32) | C40: =SUM(H29:H32) | D40: =SUM(I29:I32) | E40: =B40+C40+D40 | F40: =E40*0.12 | G40: =(E40+F40)*'S01_Disclaimer_Assumptions'!$B$38 | H40: =E40+F40+G40 | I40: 175000 | J40: =I40-H40 | K40: =J40/H40
A41: GRAND TOTAL | B41: =SUM(B36:B40) | C41: =SUM(C36:C40) | D41: =SUM(D36:D40) | E41: =SUM(E36:E40) | F41: =SUM(F36:F40) | G41: =SUM(G36:G40) | H41: =SUM(H36:H40) | I41: =SUM(I36:I40) | J41: =SUM(J36:J40) | K41: =J41/H41

Sheet S05_TCO_Downtime_Model
A1: S05 — Total Cost of Ownership (TCO) & Downtime Risk Model — 10-Year Lifecycle Analysis
A2: Compares Supplier A (Premium — TEL/AMAT-type) vs Supplier B (Value — domestic alternative) across purchase, energy, maintenance, downtime, and lifecycle NPV | Discount Rate from S01_Disclaimer_Assumptions
A4: MODEL PARAMETERS (linked from S01_Disclaimer_Assumptions)
A5: Discount Rate (WACC) | B5: ='S01_Disclaimer_Assumptions'!$B$15
A6: Project Horizon (Years) | B6: 10
A7: Energy Price (USD/kWh) | B7: ='S01_Disclaimer_Assumptions'!$B$8
A8: Production Value per Hour (USD/hr) | B8: ='S01_Disclaimer_Assumptions'!$B$33
A9: Inflation Rate | B9: ='S01_Disclaimer_Assumptions'!$B$19
A11: EQUIPMENT COMPARISON — SUPPLIER A (PREMIUM) vs SUPPLIER B (VALUE)
A12: Cost Parameter | B12: Supplier A (Premium) | C12: Supplier B (Value) | D12: Delta (B-A) | E12: Notes
A13: Purchase Price (per unit, USD) | B13: 680000 | C13: 520000 | D13: =C13-B13 | E13: Supplier A = TEL EQ-004 type; Supplier B = domestic alternative
A14: Quantity | B14: 2 | C14: 2 | D14: =C14-B14 | E14: Equal quantity for fair comparison
A15: Installation Cost (per unit, USD) | B15: 52000 | C15: 38000 | D15: =C15-B15 | E15: Supplier A requires specialized installation crew (JPY contract)
A16: Energy Consumption (kWh/hr) | B16: 110 | C16: 98 | D16: =C16-B16 | E16: Supplier A higher thermal efficiency spec; Supplier B 11% higher power draw
A17: Operational Hours (Annual) | B17: 8320 | C17: 8320 | D17: =C17-B17 | E17: Both operate on identical shift schedule
A18: Maintenance Rate (% of purchase) | B18: 0.045 | C18: 0.055 | D18: =C18-B18 | E18: Supplier A lower maint rate; Supplier B higher due to older platform design
A19: Expected MTBF (hrs) | B19: 4200 | C19: 2800 | D19: =C19-B19 | E19: Mean Time Between Failures; Supplier A more robust platform
A20: Expected MTTR (hrs) | B20: 6 | C20: 10 | D20: =C20-B20 | E20: Mean Time To Repair; Supplier A has faster FSE response SLA
A21: Spare Parts Annual Cost (USD) | B21: 18000 | C21: 28000 | D21: =C21-B21 | E21: Supplier A proprietary spares expensive but fewer events; B more frequent
A22: Expected Equipment Lifetime (yrs) | B22: 15 | C22: 12 | D22: =C22-B22 | E22: Supplier A longer qualified life; Supplier B 12 yr basis
A23: Residual Value at End of Life (%) | B23: 0.05 | C23: 0.03 | D23: =C23-B23 | E23: Estimated salvage/residual as % of purchase price
A25: 10-YEAR LIFECYCLE COST MODEL
A26: Cost Component / Supplier | B26: Y1 | C26: Y2 | D26: Y3 | E26: Y4 | F26: Y5 | G26: Y6 | H26: Y7 | I26: Y8 | J26: Y9 | K26: Y10 | L26: 10-Yr Total | M26: NPV (10-Yr)
A27: 1. Purchase Cost (total)
A28: Supplier A | B28: =680000*2 | C28: 0 | D28: 0 | E28: 0 | F28: 0 | G28: 0 | H28: 0 | I28: 0 | J28: 0 | K28: 0 | L28: =SUM(B28:K28) | M28: =NPV('S01_Disclaimer_Assumptions'!$B$15,B28:K28)
A29: Supplier B | B29: =520000*2 | C29: 0 | D29: 0 | E29: 0 | F29: 0 | G29: 0 | H29: 0 | I29: 0 | J29: 0 | K29: 0 | L29: =SUM(B29:K29) | M29: =NPV('S01_Disclaimer_Assumptions'!$B$15,B29:K29)
A30: 2. Installation Cost (total)
A31: Supplier A | B31: =52000*2 | C31: 0 | D31: 0 | E31: 0 | F31: 0 | G31: 0 | H31: 0 | I31: 0 | J31: 0 | K31: 0 | L31: =SUM(B31:K31) | M31: =NPV('S01_Disclaimer_Assumptions'!$B$15,B31:K31)
A32: Supplier B | B32: =38000*2 | C32: 0 | D32: 0 | E32: 0 | F32: 0 | G32: 0 | H32: 0 | I32: 0 | J32: 0 | K32: 0 | L32: =SUM(B32:K32) | M32: =NPV('S01_Disclaimer_Assumptions'!$B$15,B32:K32)
A33: 3. Annual Energy Cost (escalates with inflation from Year 2)
A34: Supplier A | B34: =110*2*8320*'S01_Disclaimer_Assumptions'!$B$8 | C34: =B34*(1+'S01_Disclaimer_Assumptions'!$B$19) | D34: =C34*(1+'S01_Disclaimer_Assumptions'!$B$19) | E34: =D34*(1+'S01_Disclaimer_Assumptions'!$B$19) | F34: =E34*(1+'S01_Disclaimer_Assumptions'!$B$19) | G34: =F34*(1+'S01_Disclaimer_Assumptions'!$B$19) | H34: =G34*(1+'S01_Disclaimer_Assumptions'!$B$19) | I34: =H34*(1+'S01_Disclaimer_Assumptions'!$B$19) | J34: =I34*(1+'S01_Disclaimer_Assumptions'!$B$19) | K34: =J34*(1+'S01_Disclaimer_Assumptions'!$B$19) | L34: =SUM(B34:K34) | M34: =NPV('S01_Disclaimer_Assumptions'!$B$15,B34:K34)
A35: Supplier B | B35: =98*2*8320*'S01_Disclaimer_Assumptions'!$B$8 | C35: =B35*(1+'S01_Disclaimer_Assumptions'!$B$19) | D35: =C35*(1+'S01_Disclaimer_Assumptions'!$B$19) | E35: =D35*(1+'S01_Disclaimer_Assumptions'!$B$19) | F35: =E35*(1+'S01_Disclaimer_Assumptions'!$B$19) | G35: =F35*(1+'S01_Disclaimer_Assumptions'!$B$19) | H35: =G35*(1+'S01_Disclaimer_Assumptions'!$B$19) | I35: =H35*(1+'S01_Disclaimer_Assumptions'!$B$19) | J35: =I35*(1+'S01_Disclaimer_Assumptions'!$B$19) | K35: =J35*(1+'S01_Disclaimer_Assumptions'!$B$19) | L35: =SUM(B35:K35) | M35: =NPV('S01_Disclaimer_Assumptions'!$B$15,B35:K35)
A36: 4. Annual Maintenance Cost (% of purchase; escalates with inflation)
A37: Supplier A | B37: =680000*2*0.045 | C37: =B37*(1+'S01_Disclaimer_Assumptions'!$B$19) | D37: =C37*(1+'S01_Disclaimer_Assumptions'!$B$19) | E37: =D37*(1+'S01_Disclaimer_Assumptions'!$B$19) | F37: =E37*(1+'S01_Disclaimer_Assumptions'!$B$19) | G37: =F37*(1+'S01_Disclaimer_Assumptions'!$B$19) | H37: =G37*(1+'S01_Disclaimer_Assumptions'!$B$19) | I37: =H37*(1+'S01_Disclaimer_Assumptions'!$B$19) | J37: =I37*(1+'S01_Disclaimer_Assumptions'!$B$19) | K37: =J37*(1+'S01_Disclaimer_Assumptions'!$B$19) | L37: =SUM(B37:K37) | M37: =NPV('S01_Disclaimer_Assumptions'!$B$15,B37:K37)
A38: Supplier B | B38: =520000*2*0.055 | C38: =B38*(1+'S01_Disclaimer_Assumptions'!$B$19) | D38: =C38*(1+'S01_Disclaimer_Assumptions'!$B$19) | E38: =D38*(1+'S01_Disclaimer_Assumptions'!$B$19) | F38: =E38*(1+'S01_Disclaimer_Assumptions'!$B$19) | G38: =F38*(1+'S01_Disclaimer_Assumptions'!$B$19) | H38: =G38*(1+'S01_Disclaimer_Assumptions'!$B$19) | I38: =H38*(1+'S01_Disclaimer_Assumptions'!$B$19) | J38: =I38*(1+'S01_Disclaimer_Assumptions'!$B$19) | K38: =J38*(1+'S01_Disclaimer_Assumptions'!$B$19) | L38: =SUM(B38:K38) | M38: =NPV('S01_Disclaimer_Assumptions'!$B$15,B38:K38)
A39: 5. Annual Spare Parts Cost (escalates with inflation)
A40: Supplier A | B40: =18000 | C40: =B40*(1+'S01_Disclaimer_Assumptions'!$B$19) | D40: =C40*(1+'S01_Disclaimer_Assumptions'!$B$19) | E40: =D40*(1+'S01_Disclaimer_Assumptions'!$B$19) | F40: =E40*(1+'S01_Disclaimer_Assumptions'!$B$19) | G40: =F40*(1+'S01_Disclaimer_Assumptions'!$B$19) | H40: =G40*(1+'S01_Disclaimer_Assumptions'!$B$19) | I40: =H40*(1+'S01_Disclaimer_Assumptions'!$B$19) | J40: =I40*(1+'S01_Disclaimer_Assumptions'!$B$19) | K40: =J40*(1+'S01_Disclaimer_Assumptions'!$B$19) | L40: =SUM(B40:K40) | M40: =NPV('S01_Disclaimer_Assumptions'!$B$15,B40:K40)
A41: Supplier B | B41: =28000 | C41: =B41*(1+'S01_Disclaimer_Assumptions'!$B$19) | D41: =C41*(1+'S01_Disclaimer_Assumptions'!$B$19) | E41: =D41*(1+'S01_Disclaimer_Assumptions'!$B$19) | F41: =E41*(1+'S01_Disclaimer_Assumptions'!$B$19) | G41: =F41*(1+'S01_Disclaimer_Assumptions'!$B$19) | H41: =G41*(1+'S01_Disclaimer_Assumptions'!$B$19) | I41: =H41*(1+'S01_Disclaimer_Assumptions'!$B$19) | J41: =I41*(1+'S01_Disclaimer_Assumptions'!$B$19) | K41: =J41*(1+'S01_Disclaimer_Assumptions'!$B$19) | L41: =SUM(B41:K41) | M41: =NPV('S01_Disclaimer_Assumptions'!$B$15,B41:K41)
A42: 6. Downtime Cost (Annual) — (Op Hrs ÷ MTBF) × MTTR × Production Value/hr
A43: Supplier A | B43: =(8320/4200)*6*'S01_Disclaimer_Assumptions'!$B$33 | C43: =(8320/4200)*6*'S01_Disclaimer_Assumptions'!$B$33 | D43: =(8320/4200)*6*'S01_Disclaimer_Assumptions'!$B$33 | E43: =(8320/4200)*6*'S01_Disclaimer_Assumptions'!$B$33 | F43: =(8320/4200)*6*'S01_Disclaimer_Assumptions'!$B$33 | G43: =(8320/4200)*6*'S01_Disclaimer_Assumptions'!$B$33 | H43: =(8320/4200)*6*'S01_Disclaimer_Assumptions'!$B$33 | I43: =(8320/4200)*6*'S01_Disclaimer_Assumptions'!$B$33 | ... K43: =(8320/4200)*6*'S01_Disclaimer_Assumptions'!$B$33 | L43: =SUM(B43:K43) | M43: =NPV('S01_Disclaimer_Assumptions'!$B$15,B43:K43)
...

Sheet S06_WBS
A1: S06 — Work Breakdown Structure (WBS) — Greenfield Expansion Phase II
A2: Program: Greenfield Expansion Phase II | Owner: Sourabh Tarodekar | Status: Active | All dates 2025 | WBS hierarchy: Level 1 = Program | Level 2 = Workstream | Level 3 = Work Package | WBS codes used as Activity IDs in S07_CPM_Master_Schedule
A4: WBS Code | B4: Level | C4: Workstream / Work Package | D4: Responsible Function | E4: Duration Est (wks) | F4: Start Wk | G4: End Wk | H4: Deliverable / Exit Criterion
A5: 1.0 | B5: 1 | C5: GREENFIELD EXPANSION PHASE II — PROGRAM | D5: Program Management | E5: 46 | F5: 1 | G5: 46 | H5: Full program from AR approval to production release
A6: 1.1 | B6: 2 | C6: PROGRAM MANAGEMENT | D6: Program Management | E6: 46 | F6: 1 | G6: 46 | H6: Program governance and control
A7: 1.1.1 | B7: 3 | C7: Program kick-off & AR execution | D7: PM / Finance | E7: 1 | F7: 1 | G7: 1 | H7: AR signed, cost centre open, PO authority issued
A8: 1.1.2 | B8: 3 | C8: Stakeholder communication plan | D8: PM / Eng Leadership | E8: 1 | F8: 1 | G8: 2 | H8: RACI matrix, communication cadence agreed
A9: 1.1.3 | B9: 3 | C9: Program schedule baseline | D9: PM / Scheduling | E9: 1 | F9: 1 | G9: 2 | H9: CPM schedule issued, baseline locked
A10: 1.1.4 | B10: 3 | C10: Weekly program review cadence | D10: PM | E10: 45 | F10: 2 | G10: 46 | H10: Weekly status reports issued throughout program
A11: 1.1.5 | B11: 3 | C11: Lessons learned & close-out report | D11: PM | E11: 1 | F11: 46 | G11: 46 | H11: Program close-out document issued
A12: 1.2 | B12: 2 | C12: SOURCING & PROCUREMENT | D12: Supply Chain / Sourcing | E12: 14 | F12: 1 | G12: 14 | H12: All long-lead POs placed; contracts executed
A13: 1.2.1 | B13: 3 | C13: RFQ issue — long-lead equipment (EQ-002,004,008,014) | D13: Sourcing | E13: 1 | F13: 1 | G13: 1 | H13: RFQs issued to shortlisted suppliers
A14: 1.2.2 | B14: 3 | C14: Supplier commercial evaluation & BAFO | D14: Sourcing | E14: 2 | F14: 1 | G14: 3 | H14: Bid tabulations complete; BAFO received
A15: 1.2.3 | B15: 3 | C15: Negotiation & contract award — EQ-014 (AMAT RTP) | D15: Sourcing / Legal | E15: 2 | F15: 2 | G15: 4 | H15: PO issued; 30% deposit paid
A16: 1.2.4 | B16: 3 | C16: Negotiation & contract award — EQ-002 (Pfeiffer TMP) | D16: Sourcing / Legal | E16: 2 | F16: 2 | G16: 4 | H16: PO issued; FX hedge confirmed
... A29: 1.3.7 | B29: 3 | C29: Cybersecurity review — Siemens DCS | D29: InfoSec / Engineering | E29: 3 | F29: 5 | G29: 8 | H29: Cybersecurity approval issued for OT network connection
A30: 1.3.8 | B30: 3 | C30: Engineering change order management | D30: Engineering | E30: ongoing | F30: 1 | G30: 46 | H30: ECO register maintained throughout program
A31: 1.4 | B31: 2 | C31: SUPPLIER FABRICATION & FAT | D31: Supply Chain / Engineering | E31: 26 | F31: 1 | G31: 27 | H31: All equipment at FAT complete; ready to ship
A32: 1.4.1 | B32: 3 | C32: EQ-014 (AMAT RTP) — manufacturing & FAT | D32: AMAT / Engineering | E32: 24 | F32: 1 | G32: 25 | H32: RTP units pass FAT; shipping released
A33: 1.4.2 | B33: 3 | C33: EQ-002 (Pfeiffer TMP) — manufacturing & FAT [CRITICAL PATH] | D33: Pfeiffer / Engineering | E33: 26 | F33: 1 | G33: 27 | H33: CRITICAL PATH: TMPs pass FAT; shipping released
A34: 1.4.3 | B34: 3 | C34: EQ-004 (TEL Batch Furnace) — manufacturing & FAT | D34: TEL / Engineering | E34: 28 | F34: 1 | G34: 29 | H34: Batch furnace FAT complete; JPY invoice settled
A35: 1.4.4 | B35: 3 | C35: EQ-003 (Thermco Tube Furnace) — manufacturing & FAT | D35: Thermco / Engineering | E35: 20 | F35: 2 | G35: 22 | H35: Tube furnace FAT at Austin TX; recipe transfer
A36: 1.4.5 | B36: 3 | C36: EQ-005 (Brooks SCARA) — manufacturing & FAT | D36: Brooks / Engineering | E36: 14 | F36: 3 | G36: 17 | H36: Robot units FAT complete; MES integration tested
A37: 1.4.6 | B37: 3 | C37: EQ-008 (Linde Bulk Gas) — manufacturing | D37: Linde / Facilities | E37: 32 | F37: 1 | G37: 33 | H37: Longest LT: bulk vessel shipped on schedule
A38: 1.4.7 | B38: 3 | C38: Remaining equipment — manufacturing & FAT | D38: Various suppliers | E38: 10-18 | F38: 2 | G38: 20 | H38: All units pass FAT; no open NCRs
A39: 1.5 | B39: 2 | C39: LOGISTICS | D39: Supply Chain / Logistics | E39: 8 | F39: 15 | G39: 28 | H39: All equipment delivered to site; no customs holds
A40: 1.5.1 | B40: 3 | C40: International freight booking — JPY equipment | D40: Logistics | E40: 2 | F40: 15 | G40: 17 | H40: TEL, Daikin, Daifuku freight booked; sea freight
A41: 1.5.2 | B41: 3 | C41: International freight booking — EUR equipment | D41: Logistics | E41: 2 | F41: 15 | G41: 17 | H41: EUR equipment freight arranged; road/air options
A42: 1.5.3 | B42: 3 | C42: Customs clearance — all international equipment | D42: Trade Compliance | E42: 2 | F42: 17 | G42: 24 | H42: Customs cleared; duty paid; no holds
A43: 1.5.4 | B43: 3 | C43: Final delivery & receipt inspection — site | D43: Logistics / Engineering | E43: 3 | F43: 18 | G43: 28 | H43: All equipment received, inspected; CRs raised if needed
A44: 1.6 | B44: 2 | C44: SITE READINESS | D44: Facilities / Civil | E44: 20 | F44: 1 | G44: 20 | H44: All utilities ready; floor loading confirmed; permits
A45: 1.6.1 | B45: 3 | C45: Structural floor reinforcement — EQ-004 zone | D45: Civil Engineering | E45: 6 | F45: 3 | G45: 9 | H45: Floor certified for 680kg/m² furnace load
A46: 1.6.2 | B46: 3 | C46: Electrical infrastructure — transformers & feeds | D46: Electrical Engineering | E46: 10 | F46: 2 | G46: 12 | H46: 480V feeds complete; EQ-011 energized
